Workbook

Sheet Overview
A1: ChronoSync | AI-Powered Attendance Reconciliation Engine
A2: Built at Tata Consultancy Services for a client's L&D attendance correction process
A4: Area | B4: Details
A5: The problem | B5: Learners submit attendance corrections in an Excel form with messy entries (mixed time formats, several missed periods in one cell, partial or comment-only rows). Turning these into an upload-ready missed time file was manual and repetitive.
A6: What the tool does | B6: Reads the correction form, validates each entry, maps learners to User IDs, normalizes times to MM/DD/YYYY HH:MM, and fills the missed time template. It also produces a per-learner validation report and summary counts.
A7: Scale shown here | B7: Sample data covers 40 learners in four program formats (1, 2, 4 and 5 days), with up to three missed periods per learner per day, so it shows the tool handling many learners, many days, and multiple breaks.
A8: Inputs | B8: 1) Attendance Corrections Form 2) Learner Email to User ID mapping file 3) Missed Time template
A9: Outputs | B9: 1) Populated Missed Time file (drop-in ready for upload) 2) Validation report per learner 3) Summary counts, plus the analysis in this workbook
A10: Tech | B10: Prompt Engineering, Microsoft Copilot, Claude, Python (pandas)
A11: Impact | B11: Processing time cut from about 30 minutes of manual work to about 30 seconds per run (see Impact sheet).
A13: Sample data scope (live counts)
A14: Measure | B14: Value
A15: Learners enrolled | B15: =SUM(Sessions!F5:F8) -> 40
A16: Form rows received | B16: =Analysis!C56 -> 59
A17: Missed-time instances extracted | B17: =Analysis!F9 -> 59
A18: Learners with missed time | B18: =Analysis!D9 -> 23
A19: Learners with multiple missed occurrences | B19: ='Validation Report'!B7 -> 14
A21: Note: all names, emails, and IDs in this workbook are fictional sample data. No client data is included.

Sheet Dashboard
A1: ChronoSync Dashboard: Attendance Correction Analytics
A2: Sample dataset: 40 learners, 4 program formats (1, 2, 4 and 5 days), multiple missed periods per day. Fictional data.
A4: Form rows received | C4: Rows accepted (valid) | E4: Missed instances found | G4: Learners with missed time | I4: Total missed hours | K4: Avg minutes per instance
A5: =Analysis!C56 -> 59 | C5: =Analysis!D50 -> 0.6440678 | E5: =Analysis!F9 -> 59 | G5: =Analysis!D9 -> 23 | I5: =Analysis!G9/60 -> 38.75 | K5: =Analysis!H9 -> 39.40678
A7: Key insights (from the sample data)
A8: 1. Scale: 59 form rows from 40 enrolled learners (38 usable rows) produced 59 missed-time instances across 1, 2, 4 and 5-day programs.
A9: 2. Multi-day effect: instances per enrolled learner are 0.42 on Day 1 and 0.80 on Day 5; the highest rate is on Day 5 (0.80) and the lowest on Day 2 (0.33).
A10: 3. Timing: the most common start hour is 09:00, and 51% of missed periods start at 13:00 or later.
A11: 4. Concentration: the top 5 of 23 affected learners account for 45% of all missed minutes, so a small group drives a large share of the volume.
A12: 5. Data quality: 38 of 59 rows (64%) were usable; the most common rejection was 'comments only' (5 rows). 16 valid rows held more than one missed period in a single day.
A13: Suggested actions: add a catch-up window after the peak hour, send check-ins from mid-program days, and validate the form at source (required end time, 24-hour format) to cut rejected rows.

Sheet Analysis
A1: Analysis tables
A2: All figures are formulas on the sample data; charts on the Dashboard read from here.
A3: A. Program summary
A4: Program | B4: Days | C4: Enrolled learners | D4: Learners with missed time | E4: % learners affected | F4: Missed instances | G4: Missed minutes | H4: Avg minutes per instance | I4: Avg instances per affected learner
A5: =Sessions!B5 -> 1-Day Workshop | B5: =Sessions!C5 -> 1 | C5: =Sessions!F5 -> 10 | D5: =COUNTIF('Validation Report'!$E$11:$E$33,A5) -> 3 | E5: =IFERROR(D5/C5,0) -> 0.3 | F5: =COUNTIF('Processed Instances'!$H$5:$H$63,A5) -> 5 | G5: =SUMIF('Processed Instances'!$H$5:$H$63,A5,'Processed Instances'!$J$5:$J$63) -> 195 | H5: =IFERROR(G5/F5,0) -> 39 | I5: =IFERROR(F5/D5,0) -> 1.6666667
A6: =Sessions!B6 -> 2-Day Bootcamp | B6: =Sessions!C6 -> 2 | C6: =Sessions!F6 -> 10 | D6: =COUNTIF('Validation Report'!$E$11:$E$33,A6) -> 3 | E6: =IFERROR(D6/C6,0) -> 0.3 | F6: =COUNTIF('Processed Instances'!$H$5:$H$63,A6) -> 5 | G6: =SUMIF('Processed Instances'!$H$5:$H$63,A6,'Processed Instances'!$J$5:$J$63) -> 255 | H6: =IFERROR(G6/F6,0) -> 51 | I6: =IFERROR(F6/D6,0) -> 1.6666667
A7: =Sessions!B7 -> 4-Day Program | B7: =Sessions!C7 -> 4 | C7: =Sessions!F7 -> 10 | D7: =COUNTIF('Validation Report'!$E$11:$E$33,A7) -> 9 | E7: =IFERROR(D7/C7,0) -> 0.9 | F7: =COUNTIF('Processed Instances'!$H$5:$H$63,A7) -> 18 | G7: =SUMIF('Processed Instances'!$H$5:$H$63,A7,'Processed Instances'!$J$5:$J$63) -> 670 | H7: =IFERROR(G7/F7,0) -> 37.222222 | I7: =IFERROR(F7/D7,0) -> 2
A8: =Sessions!B8 -> 5-Day Academy | B8: =Sessions!C8 -> 5 | C8: =Sessions!F8 -> 10 | D8: =COUNTIF('Validation Report'!$E$11:$E$33,A8) -> 8 | E8: =IFERROR(D8/C8,0) -> 0.8 | F8: =COUNTIF('Processed Instances'!$H$5:$H$63,A8) -> 31 | G8: =SUMIF('Processed Instances'!$H$5:$H$63,A8,'Processed Instances'!$J$5:$J$63) -> 1205 | H8: =IFERROR(G8/F8,0) -> 38.870968 | I8: =IFERROR(F8/D8,0) -> 3.875
A9: Total | C9: =SUM(C5:C8) -> 40 | D9: =SUM(D5:D8) -> 23 | E9: =IFERROR(D9/C9,0) -> 0.575 | F9: =SUM(F5:F8) -> 59 | G9: =SUM(G5:G8) -> 2325 | H9: =IFERROR(G9/F9,0) -> 39.40678 | I9: =IFERROR(F9/D9,0) -> 2.5652174
A12: B. Missed time by session day
A13: Day | B13: Day # | C13: 1-Day Workshop | D13: 2-Day Bootcamp | E13: 4-Day Program | F13: 5-Day Academy | G13: Total instances | H13: Learners in session that day | I13: Instances per learner | J13: Missed minutes | K13: Avg minutes per instance
A14: Day 1 | B14: 1 | C14: =COUNTIFS('Processed Instances'!$H$5:$H$63,C$13,'Processed Instances'!$I$5:$I$63,$B14) -> 5 | D14: =COUNTIFS('Processed Instances'!$H$5:$H$63,D$13,'Processed Instances'!$I$5:$I$63,$B14) -> 2 | E14: =COUNTIFS('Processed Instances'!$H$5:$H$63,E$13,'Processed Instances'!$I$5:$I$63,$B14) -> 6 | F14: =COUNTIFS('Processed Instances'!$H$5:$H$63,F$13,'Processed Instances'!$I$5:$I$63,$B14) -> 4 | G14: =SUM(C14:F14) -> 17 | H14: =SUMIF(Sessions!$C$5:$C$8,">="&B14,Sessions!$F$5:$F$8) -> 40 | I14: =IFERROR(G14/H14,0) -> 0.425 | J14: =SUMIF('Processed Instances'!$I$5:$I$63,B14,'Processed Instances'!$J$5:$J$63) -> 685 | K14: =IFERROR(J14/G14,0) -> 40.294118
A15: Day 2 | B15: 2 | C15: =COUNTIFS('Processed Instances'!$H$5:$H$63,C$13,'Processed Instances'!$I$5:$I$63,$B15) -> 0 | D15: =COUNTIFS('Processed Instances'!$H$5:$H$63,D$13,'Processed Instances'!$I$5:$I$63,$B15) -> 3 | E15: =COUNTIFS('Processed Instances'!$H$5:$H$63,E$13,'Processed Instances'!$I$5:$I$63,$B15) -> 1 | F15: =COUNTIFS('Processed Instances'!$H$5:$H$63,F$13,'Processed Instances'!$I$5:$I$63,$B15) -> 6 | G15: =SUM(C15:F15) -> 10 | H15: =SUMIF(Sessions!$C$5:$C$8,">="&B15,Sessions!$F$5:$F$8) -> 30 | I15: =IFERROR(G15/H15,0) -> 0.33333333 | J15: =SUMIF('Processed Instances'!$I$5:$I$63,B15,'Processed Instances'!$J$5:$J$63) -> 370 | K15: =IFERROR(J15/G15,0) -> 37
A16: Day 3 | B16: 3 | C16: =COUNTIFS('Processed Instances'!$H$5:$H$63,C$13,'Processed Instances'!$I$5:$I$63,$B16) -> 0 | D16: =COUNTIFS('Processed Instances'!$H$5:$H$63,D$13,'Processed Instances'!$I$5:$I$63,$B16) -> 0 | E16: =COUNTIFS('Processed Instances'!$H$5:$H$63,E$13,'Processed Instances'!$I$5:$I$63,$B16) -> 7 | F16: =COUNTIFS('Processed Instances'!$H$5:$H$63,F$13,'Processed Instances'!$I$5:$I$63,$B16) -> 7 | G16: =SUM(C16:F16) -> 14 | H16: =SUMIF(Sessions!$C$5:$C$8,">="&B16,Sessions!$F$5:$F$8) -> 20 | I16: =IFERROR(G16/H16,0) -> 0.7 | J16: =SUMIF('Processed Instances'!$I$5:$I$63,B16,'Processed Instances'!$J$5:$J$63) -> 620 | K16: =IFERROR(J16/G16,0) -> 44.285714
A17: Day 4 | B17: 4 | C17: =COUNTIFS('Processed Instances'!$H$5:$H$63,C$13,'Processed Instances'!$I$5:$I$63,$B17) -> 0 | D17: =COUNTIFS('Processed Instances'!$H$5:$H$63,D$13,'Processed Instances'!$I$5:$I$63,$B17) -> 0 | E17: =COUNTIFS('Processed Instances'!$H$5:$H$63,E$13,'Processed Instances'!$I$5:$I$63,$B17) -> 4 | F17: =COUNTIFS('Processed Instances'!$H$5:$H$63,F$13,'Processed Instances'!$I$5:$I$63,$B17) -> 6 | G17: =SUM(C17:F17) -> 10 | H17: =SUMIF(Sessions!$C$5:$C$8,">="&B17,Sessions!$F$5:$F$8) -> 20 | I17: =IFERROR(G17/H17,0) -> 0.5 | J17: =SUMIF('Processed Instances'!$I$5:$I$63,B17,'Processed Instances'!$J$5:$J$63) -> 405 | K17: =IFERROR(J17/G17,0) -> 40.5
A18: Day 5 | B18: 5 | C18: =COUNTIFS('Processed Instances'!$H$5:$H$63,C$13,'Processed Instances'!$I$5:$I$63,$B18) -> 0 | D18: =COUNTIFS('Processed Instances'!$H$5:$H$63,D$13,'Processed Instances'!$I$5:$I$63,$B18) -> 0 | E18: =COUNTIFS('Processed Instances'!$H$5:$H$63,E$13,'Processed Instances'!$I$5:$I$63,$B18) -> 0 | F18: =COUNTIFS('Processed Instances'!$H$5:$H$63,F$13,'Processed Instances'!$I$5:$I$63,$B18) -> 8 | G18: =SUM(C18:F18) -> 8 | H18: =SUMIF(Sessions!$C$5:$C$8,">="&B18,Sessions!$F$5:$F$8) -> 10 | I18: =IFERROR(G18/H18,0) -> 0.8 | J18: =SUMIF('Processed Instances'!$I$5:$I$63,B18,'Processed Instances'!$J$5:$J$63) -> 245 | K18: =IFERROR(J18/G18,0) -> 30.625
A21: C. Missed time by start hour
A22: Start hour | B22: Hour | C22: Missed instances | D22: Missed minutes
A23: 09:00 | B23: 9 | C23: =COUNTIF('Processed Instances'!$K$5:$K$63,B23) -> 12 | D23: =SUMIF('Processed Instances'!$K$5:$K$63,B23,'Processed Instances'!$J$5:$J$63) -> 405
A24: 10:00 | B24: 10 | C24: =COUNTIF('Processed Instances'!$K$5:$K$63,B24) -> 8 | D24: =SUMIF('Processed Instances'!$K$5:$K$63,B24,'Processed Instances'!$J$5:$J$63) -> 365
A25: 11:00 | B25: 11 | C25: =COUNTIF('Processed Instances'!$K$5:$K$63,B25) -> 8 | D25: =SUMIF('Processed Instances'!$K$5:$K$63,B25,'Processed Instances'!$J$5:$J$63) -> 300
A26: 12:00 | B26: 12 | C26: =COUNTIF('Processed Instances'!$K$5:$K$63,B26) -> 1 | D26: =SUMIF('Processed Instances'!$K$5:$K$63,B26,'Processed Instances'!$J$5:$J$63) -> 45
A27: 13:00 | B27: 13 | C27: =COUNTIF('Processed Instances'!$K$5:$K$63,B27) -> 10 | D27: =SUMIF('Processed Instances'!$K$5:$K$63,B27,'Processed Instances'!$J$5:$J$63) -> 480
A28: 14:00 | B28: 14 | C28: =COUNTIF('Processed Instances'!$K$5:$K$63,B28) -> 10 | D28: =SUMIF('Processed Instances'!$K$5:$K$63,B28,'Processed Instances'!$J$5:$J$63) -> 475
A29: 15:00 | B29: 15 | C29: =COUNTIF('Processed Instances'!$K$5:$K$63,B29) -> 7 | D29: =SUMIF('Processed Instances'!$K$5:$K$63,B29,'Processed Instances'!$J$5:$J$63) -> 185
A30: 16:00 | B30: 16 | C30: =COUNTIF('Processed Instances'!$K$5:$K$63,B30) -> 3 | D30: =SUMIF('Processed Instances'!$K$5:$K$63,B30,'Processed Instances'!$J$5:$J$63) -> 70
A33: D. Top 10 learners by missed minutes
A34: Rank | B34: Learner | C34: Program | D34: Missed minutes | E34: Missed instances
A35: 1 | B35: Kiran Bhat | C35: =INDEX('Processed Instances'!$H$5:$H$63,MATCH(B35,'Processed Instances'!$B$5:$B$63,0)) -> 5-Day Academy | D35: =SUMIF('Processed Instances'!$B$5:$B$63,B35,'Processed Instances'!$J$5:$J$63) -> 255 | E35: =COUNTIF('Processed Instances'!$B$5:$B$63,B35) -> 8
A36: 2 | B36: Omar Pillai | C36: =INDEX('Processed Instances'!$H$5:$H$63,MATCH(B36,'Processed Instances'!$B$5:$B$63,0)) -> 5-Day Academy | D36: =SUMIF('Processed Instances'!$B$5:$B$63,B36,'Processed Instances'!$J$5:$J$63) -> 250 | E36: =COUNTIF('Processed Instances'!$B$5:$B$63,B36) -> 5
A37: 3 | B37: Faisal Hassan | C37: =INDEX('Processed Instances'!$H$5:$H$63,MATCH(B37,'Processed Instances'!$B$5:$B$63,0)) -> 5-Day Academy | D37: =SUMIF('Processed Instances'!$B$5:$B$63,B37,'Processed Instances'!$J$5:$J$63) -> 200 | E37: =COUNTIF('Processed Instances'!$B$5:$B$63,B37) -> 5
A38: 4 | B38: Anil Verma | C38: =INDEX('Processed Instances'!$H$5:$H$63,MATCH(B38,'Processed Instances'!$B$5:$B$63,0)) -> 4-Day Program | D38: =SUMIF('Processed Instances'!$B$5:$B$63,B38,'Processed Instances'!$J$5:$J$63) -> 170 | E38: =COUNTIF('Processed Instances'!$B$5:$B$63,B38) -> 4
A39: 5 | B39: Xavier Fischer | C39: =INDEX('Processed Instances'!$H$5:$H$63,MATCH(B39,'Processed Instances'!$B$5:$B$63,0)) -> 4-Day Program | D39: =SUMIF('Processed Instances'!$B$5:$B$63,B39,'Processed Instances'!$J$5:$J$63) -> 165 | E39: =COUNTIF('Processed Instances'!$B$5:$B$63,B39) -> 3
A40: 6 | B40: Marco Rossi | C40: =INDEX('Processed Instances'!$H$5:$H$63,MATCH(B40,'Processed Instances'!$B$5:$B$63,0)) -> 5-Day Academy | D40: =SUMIF('Processed Instances'!$B$5:$B$63,B40,'Processed Instances'!$J$5:$J$63) -> 160 | E40: =COUNTIF('Processed Instances'!$B$5:$B$63,B40) -> 3
A41: 7 | B41: Tariq Ali | C41: =INDEX('Processed Instances'!$H$5:$H$63,MATCH(B41,'Processed Instances'!$B$5:$B$63,0)) -> 2-Day Bootcamp | D41: =SUMIF('Processed Instances'!$B$5:$B$63,B41,'Processed Instances'!$J$5:$J$63) -> 120 | E41: =COUNTIF('Processed Instances'!$B$5:$B$63,B41) -> 3
A42: 8 | B42: Leela Hughes | C42: =INDEX('Processed Instances'!$H$5:$H$63,MATCH(B42,'Processed Instances'!$B$5:$B$63,0)) -> 5-Day Academy | D42: =SUMIF('Processed Instances'!$B$5:$B$63,B42,'Processed Instances'!$J$5:$J$63) -> 105 | E42: =COUNTIF('Processed Instances'!$B$5:$B$63,B42) -> 5
A43: 9 | B43: Ben Carter | C43: =INDEX('Processed Instances'!$H$5:$H$63,MATCH(B43,'Processed Instances'!$B$5:$B$63,0)) -> 1-Day Workshop | D43: =SUMIF('Processed Instances'!$B$5:$B$63,B43,'Processed Instances'!$J$5:$J$63) -> 90 | E43: =COUNTIF('Processed Instances'!$B$5:$B$63,B43) -> 2
A44: 10 | B44: Elena Ortiz | C44: =INDEX('Processed Instances'!$H$5:$H$63,MATCH(B44,'Processed Instances'!$B$5:$B$63,0)) -> 4-Day Program | D44: =SUMIF('Processed Instances'!$B$5:$B$63,B44,'Processed Instances'!$J$5:$J$63) -> 90 | E44: =COUNTIF('Processed Instances'!$B$5:$B$63,B44) -> 3
A45: Top 10 share of all missed minutes | D45: =SUM(D35:D44)/G9 -> 0.69032258
A48: E. Data quality: what happens to each form row
...

Sheet Workflow
A1: How it works: pipeline steps
A2: Ingestion, validation, mapping, output, analysis
A4: Step | B4: Stage | C4: What happens | D4: Rule applied | E4: Tool
A5: 1 | B5: Ingestion | C5: Reads the corrections workbook and auto-detects the header row | D5: Header row found by matching column names | E5: Python (pandas)
A6: 2 | B6: Cleaning | C6: Cleans learner emails and splits multi-entry time cells | D6: Trim, lowercase, remove mailto/brackets; split on new line or comma | E6: Python / Prompt
A7: 3 | B7: Filtering | C7: Keeps only complete missed-time records | D7: Both start and end required; partial and comment-only rows dropped; excluded emails dropped | E7: Prompt (Copilot, Claude)
A8: 4 | B8: Time normalization | C8: Converts 9am, 1:06 PM, 13:06 etc. into one standard format | D8: Output MM/DD/YYYY HH:MM, 24-hour, no AM/PM | E8: Python / Prompt
A9: 5 | B9: Time validation | C9: Removes impossible time ranges | D9: End time before or equal to start is invalid; no next-day inference | E9: Python / Prompt
A10: 6 | B10: User ID mapping | C10: Joins learner email to User ID | D10: Unmapped learners are excluded; User IDs are never guessed | E10: Python (pandas)
A11: 7 | B11: Output | C11: Fills only the required template columns and builds the validation report | D11: Template structure preserved; other columns left blank | E11: Python / Prompt
A12: 8 | B12: Analysis | C12: Summarizes missed time by program, session day, hour, and learner | D12: Counts and minutes aggregated from the processed instances | E12: Excel formulas

Sheet Sessions
A1: Sessions in the sample data
A2: Four program formats: 1, 2, 4 and 5 days (fictional)
A4: Session ID | B4: Program | C4: Days | D4: Start date | E4: End date | F4: Enrolled learners
A5: S-101 | B5: 1-Day Workshop | C5: 1 | D5: 45936 | E5: =D5+C5-1 -> 45936 | F5: 10
A6: S-102 | B6: 2-Day Bootcamp | C6: 2 | D6: 45937 | E6: =D6+C6-1 -> 45938 | F6: 10
A7: S-103 | B7: 4-Day Program | C7: 4 | D7: 45943 | E7: =D7+C7-1 -> 45946 | F7: 10
A8: S-104 | B8: 5-Day Academy | C8: 5 | D8: 45950 | E8: =D8+C8-1 -> 45954 | F8: 10
A10: Enrolled learners (blue) are sample inputs. All sessions run on consecutive weekdays.

Sheet Sample Mapping
A1: Sample User ID mapping file
A2: Learner Email to User ID (fictional). Some learners are intentionally missing.
A4: Learner Email | B4: User ID
A5: asha.rao@example.com | B5: U1001
A6: ben.carter@example.com | B6: U1002
A7: chitra.nair@example.com | B7: U1003
A8: dev.patel@example.com | B8: U1004
A9: farah.khan@example.com | B9: U1005
A10: gita.menon@example.com | B10: U1006
A11: hiro.tanaka@example.com | B11: U1007
A12: isha.sharma@example.com | B12: U1008
A13: jon.brooks@example.com | B13: U1009
A14: kavya.iyer@example.com | B14: U1010
A15: liam.murphy@example.com | B15: U1011
... A42: omar.pillai@example.com | B42: U1038

Sheet Learner Roster
A1: Learner roster with Session Learning Object IDs
A2: All 40 enrolled learners. IDs are fictional random placeholders (24+ characters) for this sample.
A4: Learner Name | B4: Learner Email | C4: User ID | D4: Session ID | E4: Session Learning Object ID | F4: ID length
A5: Asha Rao | B5: asha.rao@example.com | C5: U1001 | D5: S-101 | E5: SLO-C48TNNINDEHNOWTC61AI22OQ | F5: =LEN(E5) -> 28
A6: Ben Carter | B6: ben.carter@example.com | C6: U1002 | D6: S-101 | E6: SLO-6VTHIB2TN9QJ3U3LQ2QY1UXV | F6: =LEN(E6) -> 28
A7: Chitra Nair | B7: chitra.nair@example.com | C7: U1003 | D7: S-101 | E7: SLO-LWIITL49KCF3TU6A69TVTF73SL | F7: =LEN(E7) -> 30
A8: Dev Patel | B8: dev.patel@example.com | C8: U1004 | D8: S-101 | E8: SLO-SUYHHFPU1JAUHFGY0J6E | F8: =LEN(E8) -> 24
A9: Farah Khan | B9: farah.khan@example.com | C9: U1005 | D9: S-101 | E9: SLO-LNO5VQG7FYLZ5XUA106MSL89F | F9: =LEN(E9) -> 29
A10: Gita Menon | B10: gita.menon@example.com | C10: U1006 | D10: S-101 | E10: SLO-SWWPL2886F5M0RGSCGM2C37EY | F10: =LEN(E10) -> 29
A11: Hiro Tanaka | B11: hiro.tanaka@example.com | C11: U1007 | D11: S-101 | E11: SLO-81IJJXXUP1UXHJWWXM108VTZ | F11: =LEN(E11) -> 28
A12: Isha Sharma | B12: isha.sharma@example.com | C12: U1008 | D12: S-101 | E12: SLO-W33OMBD4K367PT6JMN1A4TQLM | F12: =LEN(E12) -> 29
A13: Jon Brooks | B13: jon.brooks@example.com | C13: U1009 | D13: S-101 | E13: SLO-ERZ1KJAAZKPG06TVX4F3JX | F13: =LEN(E13) -> 26
A14: Kavya Iyer | B14: kavya.iyer@example.com | C14: U1010 | D14: S-101 | E14: SLO-QGI2D0KEJJC3TNWHB6E5KA6 | F14: =LEN(E14) -> 27
A15: Liam Murphy | B15: liam.murphy@example.com | C15: U1011 | D15: S-102 | E15: SLO-AMFK2A87YFF1W7DB19FE1 | F15: =LEN(E15) -> 25
A16: Meera Das | B16: meera.das@example.com | C16: U1012 | D16: S-102 | E16: SLO-WEUOILTWKHL2FQNBGEEG1 | F16: =LEN(E16) -> 25
... A44: Omar Pillai | B44: omar.pillai@example.com | C44: U1038 | D44: S-104 | E44: SLO-VSIXVAUKOVQNW8DCCEIGKHY | F44: =LEN(E44) -> 27
A46: Minimum ID length in this roster: | E46: =MIN(F5:F44) -> 24
A47: In the real tool, Session Learning Object IDs come from the template or source system and are never generated or guessed.

Sheet Sample Input
A1: Sample input: Attendance Corrections Form (messy, as received)
A2: Fictional data. Mixed time formats, several breaks in one cell, and invalid rows. Outcome shows what the tool does with each row.
A4: Session ID | B4: Learner Name | C4: Learner Email Address | D4: Date (MM/DD/YYYY) | E4: Missed Time Start | F4: Missed Time End | G4: Comments | H4: Mapped User ID? | I4: Outcome | J4: Missed periods in cell
A5: S-101 | B5: Asha Rao | C5: asha.rao@example.com | D5: 10/06/2025 | G5: Joined late, will update | H5: =IF(ISNUMBER(MATCH(LOWER(TRIM(C5)),'Sample Mapping'!$A$5:$A$42,0)),"Yes","No") -> Yes | I5: Excluded: comments only | J5: =IF(E5="",0,LEN(E5)-LEN(SUBSTITUTE(E5,CHAR(10),""))+1) -> 0
A6: S-101 | B6: Ben Carter | C6: BEN.CARTER@EXAMPLE.COM | D6: 10/06/2025 | E6: 9:40 11:00 | F6: 9:55 12:15 | G6: Platform glitch | H6: =IF(ISNUMBER(MATCH(LOWER(TRIM(C6)),'Sample Mapping'!$A$5:$A$42,0)),"Yes","No") -> Yes | I6: Valid | J6: =IF(E6="",0,LEN(E6)-LEN(SUBSTITUTE(E6,CHAR(10),""))+1) -> 2
A7: S-101 | B7: Chitra Nair | C7: chitra.nair@example.com | D7: 10/06/2025 | E7: 10:00 | G7: End time not noted | H7: =IF(ISNUMBER(MATCH(LOWER(TRIM(C7)),'Sample Mapping'!$A$5:$A$42,0)),"Yes","No") -> Yes | I7: Excluded: end time missing | J7: =IF(E7="",0,LEN(E7)-LEN(SUBSTITUTE(E7,CHAR(10),""))+1) -> 1
A8: S-101 | B8: Dev Patel | C8: dev.patel@example.com | D8: 10/06/2025 | E8: 9:45 | F8: 10:00 | H8: =IF(ISNUMBER(MATCH(LOWER(TRIM(C8)),'Sample Mapping'!$A$5:$A$42,0)),"Yes","No") -> Yes | I8: Valid | J8: =IF(E8="",0,LEN(E8)-LEN(SUBSTITUTE(E8,CHAR(10),""))+1) -> 1
A9: S-101 | B9: Farah Khan | C9: farah.khan@example.com | D9: 10/06/2025 | G9: Left early for another meeting | H9: =IF(ISNUMBER(MATCH(LOWER(TRIM(C9)),'Sample Mapping'!$A$5:$A$42,0)),"Yes","No") -> Yes | I9: Excluded: comments only | J9: =IF(E9="",0,LEN(E9)-LEN(SUBSTITUTE(E9,CHAR(10),""))+1) -> 0
A10: S-101 | B10: Jon Brooks | C10: jon.brooks@example.com | D10: 10/06/2025 | E10: 10:10 AM 3:10 PM | F10: 11:25 AM 3:25 PM | G10: Audio problem | H10: =IF(ISNUMBER(MATCH(LOWER(TRIM(C10)),'Sample Mapping'!$A$5:$A$42,0)),"Yes","No") -> Yes | I10: Valid | J10: =IF(E10="",0,LEN(E10)-LEN(SUBSTITUTE(E10,CHAR(10),""))+1) -> 2
A11: S-102 | B11: Priya Singh | C11: PRIYA.SINGH@EXAMPLE.COM | D11: 10/07/2025 | E11: 2:10pm | F11: 3:10pm | H11: =IF(ISNUMBER(MATCH(LOWER(TRIM(C11)),'Sample Mapping'!$A$5:$A$42,0)),"Yes","No") -> No | I11: Excluded: no User ID found | J11: =IF(E11="",0,LEN(E11)-LEN(SUBSTITUTE(E11,CHAR(10),""))+1) -> 1
A12: S-102 | B12: Quinn Lopez | C12: quinn.lopez@example.com | D12: 10/07/2025 | E12: 2pm | F12: 1pm | G12: Typed times wrongly | H12: =IF(ISNUMBER(MATCH(LOWER(TRIM(C12)),'Sample Mapping'!$A$5:$A$42,0)),"Yes","No") -> Yes | I12: Excluded: end before start | J12: =IF(E12="",0,LEN(E12)-LEN(SUBSTITUTE(E12,CHAR(10),""))+1) -> 1
A13: S-102 | B13: Tariq Ali | C13: tariq.ali@example.com | D13: 10/07/2025 | E13: 10:30 14:50 | F13: 11:10 15:50 | G13: Rejoined after break | H13: =IF(ISNUMBER(MATCH(LOWER(TRIM(C13)),'Sample Mapping'!$A$5:$A$42,0)),"Yes","No") -> Yes | I13: Valid | J13: =IF(E13="",0,LEN(E13)-LEN(SUBSTITUTE(E13,CHAR(10),""))+1) -> 2
A14: S-102 | B14: Liam Murphy | C14: liam.murphy@example.com | D14: 10/08/2025 | E14: 10:50am | F14: 12:05pm | H14: =IF(ISNUMBER(MATCH(LOWER(TRIM(C14)),'Sample Mapping'!$A$5:$A$42,0)),"Yes","No") -> Yes | I14: Valid | J14: =IF(E14="",0,LEN(E14)-LEN(SUBSTITUTE(E14,CHAR(10),""))+1) -> 1
A15: S-102 | B15: Olivia Reed | C15: olivia.reed@example.com | D15: 10/08/2025 | E15: 1:25pm | F15: 2:25pm | G15: Client call | H15: =IF(ISNUMBER(MATCH(LOWER(TRIM(C15)),'Sample Mapping'!$A$5:$A$42,0)),"Yes","No") -> Yes | I15: Valid | J15: =IF(E15="",0,LEN(E15)-LEN(SUBSTITUTE(E15,CHAR(10),""))+1) -> 1
A16: S-102 | B16: Priya Singh | C16: priya.singh@example.com | D16: 10/08/2025 | E16: 2:25 PM | F16: 3:05 PM | H16: =IF(ISNUMBER(MATCH(LOWER(TRIM(C16)),'Sample Mapping'!$A$5:$A$42,0)),"Yes","No") -> No | I16: Excluded: no User ID found | J16: =IF(E16="",0,LEN(E16)-LEN(SUBSTITUTE(E16,CHAR(10),""))+1) -> 1
A17: S-102 | B17: Tariq Ali | C17: tariq.ali@example.com | D17: 10/08/2025 | E17: 9:20 AM | F17: 9:40 AM | G17: Platform glitch | H17: =IF(ISNUMBER(MATCH(LOWER(TRIM(C17)),'Sample Mapping'!$A$5:$A$42,0)),"Yes","No") -> Yes | I17: Valid | J17: =IF(E17="",0,LEN(E17)-LEN(SUBSTITUTE(E17,CHAR(10),""))+1) -> 1
A18: S-103 | B18: Bianca Silva | C18: bianca.silva@example.com | D18: 10/13/2025 | E18: 2pm | F18: 2:30pm | H18: =IF(ISNUMBER(MATCH(LOWER(TRIM(C18)),'Sample Mapping'!$A$5:$A$42,0)),"Yes","No") -> Yes | I18: Valid | J18: =IF(E18="",0,LEN(E18)-LEN(SUBSTITUTE(E18,CHAR(10),""))+1) -> 1
A19: S-103 | B19: Elena Ortiz | C19: elena.ortiz@example.com | D19: 10/13/2025 | E19: 1:10 PM 3:55 PM | F19: 1:55 PM 4:20 PM | G19: Platform glitch | H19: =IF(ISNUMBER(MATCH(LOWER(TRIM(C19)),'Sample Mapping'!$A$5:$A$42,0)),"Yes","No") -> Yes | I19: Valid | J19: =IF(E19="",0,LEN(E19)-LEN(SUBSTITUTE(E19,CHAR(10),""))+1) -> 2
A20: S-103 | B20: Excluded User 1 | C20: excluded.user1@example.com | D20: 10/13/2025 | E20: 10:00 | F20: 10:30 | H20: =IF(ISNUMBER(MATCH(LOWER(TRIM(C20)),'Sample Mapping'!$A$5:$A$42,0)),"Yes","No") -> No | I20: Excluded: on exclusion list | J20: =IF(E20="",0,LEN(E20)-LEN(SUBSTITUTE(E20,CHAR(10),""))+1) -> 1
A21: S-103 | B21: Vikram Bose | C21: vikram.bose@example.com | D21: 10/13/2025 | E21: 10:10 AM | F21: 10:55 AM | G21: Platform glitch | H21: =IF(ISNUMBER(MATCH(LOWER(TRIM(C21)),'Sample Mapping'!$A$5:$A$42,0)),"Yes","No") -> Yes | I21: Valid | J21: =IF(E21="",0,LEN(E21)-LEN(SUBSTITUTE(E21,CHAR(10),""))+1) -> 1
A22: S-103 | B22: Yara Ahmed | C22: yara.ahmed@example.com | D22: 10/13/2025 | E22: 9:45 13:25 | F22: 10:05 13:35 | H22: =IF(ISNUMBER(MATCH(LOWER(TRIM(C22)),'Sample Mapping'!$A$5:$A$42,0)),"Yes","No") -> Yes | I22: Valid | J22: =IF(E22="",0,LEN(E22)-LEN(SUBSTITUTE(E22,CHAR(10),""))+1) -> 2
A23: S-103 | B23: Excluded User 1 | C23: excluded.user1@example.com | D23: 10/14/2025 | E23: 10:00 | F23: 10:30 | H23: =IF(ISNUMBER(MATCH(LOWER(TRIM(C23)),'Sample Mapping'!$A$5:$A$42,0)),"Yes","No") -> No | I23: Excluded: on exclusion list | J23: =IF(E23="",0,LEN(E23)-LEN(SUBSTITUTE(E23,CHAR(10),""))+1) -> 1
A24: S-103 | B24: Wen Chen | C24: wen.chen@example.com | D24: 10/14/2025 | E24: 9:40 AM | F24: 10:20 AM | G24: Laptop issue | H24: =IF(ISNUMBER(MATCH(LOWER(TRIM(C24)),'Sample Mapping'!$A$5:$A$42,0)),"Yes","No") -> Yes | I24: Valid | J24: =IF(E24="",0,LEN(E24)-LEN(SUBSTITUTE(E24,CHAR(10),""))+1) -> 1
A25: S-103 | B25: Anil Verma | C25: anil.verma@example.com | D25: 10/15/2025 | E25: 11:55 13:10 15:40 | F25: 13:10 13:50 16:10 | H25: =IF(ISNUMBER(MATCH(LOWER(TRIM(C25)),'Sample Mapping'!$A$5:$A$42,0)),"Yes","No") -> Yes | I25: Valid | J25: =IF(E25="",0,LEN(E25)-LEN(SUBSTITUTE(E25,CHAR(10),""))+1) -> 3
A26: S-103 | B26: Wen Chen | C26: wen.chen@example.com | D26: 10/15/2025 | E26: 2pm | F26: 1pm | G26: Typed times wrongly | H26: =IF(ISNUMBER(MATCH(LOWER(TRIM(C26)),'Sample Mapping'!$A$5:$A$42,0)),"Yes","No") -> Yes | I26: Excluded: end before start | J26: =IF(E26="",0,LEN(E26)-LEN(SUBSTITUTE(E26,CHAR(10),""))+1) -> 1
A27: S-103 | B27: Xavier Fischer | C27: Xavier.fischer@example.com | D27: 10/15/2025 | E27: 9:50 11:30 14:50 | F27: 10:35 12:15 16:05 | G27: Audio problem | H27: =IF(ISNUMBER(MATCH(LOWER(TRIM(C27)),'Sample Mapping'!$A$5:$A$42,0)),"Yes","No") -> Yes | I27: Valid | J27: =IF(E27="",0,LEN(E27)-LEN(SUBSTITUTE(E27,CHAR(10),""))+1) -> 3
A28: S-103 | B28: Zane Kapoor | C28: zane.kapoor@example.com | D28: 10/15/2025 | E28: 11:10 AM | F28: 11:25 AM | G28: Connection lost | H28: =IF(ISNUMBER(MATCH(LOWER(TRIM(C28)),'Sample Mapping'!$A$5:$A$42,0)),"Yes","No") -> Yes | I28: Valid | J28: =IF(E28="",0,LEN(E28)-LEN(SUBSTITUTE(E28,CHAR(10),""))+1) -> 1
A29: S-103 | B29: Anil Verma | C29: anil.verma@example.com | D29: 10/16/2025 | E29: 3:15pm | F29: 3:40pm | G29: Audio problem | H29: =IF(ISNUMBER(MATCH(LOWER(TRIM(C29)),'Sample Mapping'!$A$5:$A$42,0)),"Yes","No") -> Yes | I29: Valid | J29: =IF(E29="",0,LEN(E29)-LEN(SUBSTITUTE(E29,CHAR(10),""))+1) -> 1
A30: S-103 | B30: Carlos Nguyen | C30: carlos.nguyen@example.com | D30: 10/16/2025 | E30: 10:15 AM | F30: 11:15 AM | H30: =IF(ISNUMBER(MATCH(LOWER(TRIM(C30)),'Sample Mapping'!$A$5:$A$42,0)),"Yes","No") -> Yes | I30: Valid | J30: =IF(E30="",0,LEN(E30)-LEN(SUBSTITUTE(E30,CHAR(10),""))+1) -> 1
A31: S-103 | B31: Elena Ortiz | C31: elena.ortiz@example.com | D31: 10/16/2025 | E31: 4 PM | F31: 4:20 PM | H31: =IF(ISNUMBER(MATCH(LOWER(TRIM(C31)),'Sample Mapping'!$A$5:$A$42,0)),"Yes","No") -> Yes | I31: Valid | J31: =IF(E31="",0,LEN(E31)-LEN(SUBSTITUTE(E31,CHAR(10),""))+1) -> 1
A32: S-103 | B32: Vikram Bose | C32: vikram.bose@example.com | D32: 10/16/2025 | E32: 9:10 AM | F32: 9:35 AM | H32: =IF(ISNUMBER(MATCH(LOWER(TRIM(C32)),'Sample Mapping'!$A$5:$A$42,0)),"Yes","No") -> Yes | I32: Valid | J32: =IF(E32="",0,LEN(E32)-LEN(SUBSTITUTE(E32,CHAR(10),""))+1) -> 1
A33: S-103 | B33: Zane Kapoor | C33: zane.kapoor@example.com | D33: 10/16/2025 | G33: Joined late, will update | H33: =IF(ISNUMBER(MATCH(LOWER(TRIM(C33)),'Sample Mapping'!$A$5:$A$42,0)),"Yes","No") -> Yes | I33: Excluded: comments only | J33: =IF(E33="",0,LEN(E33)-LEN(SUBSTITUTE(E33,CHAR(10),""))+1) -> 0
A34: S-104 | B34: Excluded User 2 | C34: excluded.user2@example.com | D34: 10/20/2025 | E34: 10:00 | F34: 10:30 | H34: =IF(ISNUMBER(MATCH(LOWER(TRIM(C34)),'Sample Mapping'!$A$5:$A$42,0)),"Yes","No") -> No | I34: Excluded: on exclusion list | J34: =IF(E34="",0,LEN(E34)-LEN(SUBSTITUTE(E34,CHAR(10),""))+1) -> 1
A35: S-104 | B35: Faisal Hassan | C35: faisal.hassan@example.com | D35: 10/20/2025 | E35: 9:40 13:10 | F35: 10:00 13:55 | G35: Audio problem | H35: =IF(ISNUMBER(MATCH(LOWER(TRIM(C35)),'Sample Mapping'!$A$5:$A$42,0)),"Yes","No") -> Yes | I35: Valid | J35: =IF(E35="",0,LEN(E35)-LEN(SUBSTITUTE(E35,CHAR(10),""))+1) -> 2
A36: S-104 | B36: Grace Park | C36: grace.park@example.com | D36: 10/20/2025 | E36: 13:05 | F36: 14:20 | H36: =IF(ISNUMBER(MATCH(LOWER(TRIM(C36)),'Sample Mapping'!$A$5:$A$42,0)),"Yes","No") -> Yes | I36: Valid | J36: =IF(E36="",0,LEN(E36)-LEN(SUBSTITUTE(E36,CHAR(10),""))+1) -> 1
A37: S-104 | B37: Harsh Malik | C37: harsh.malik@example.com | D37: 10/20/2025 | E37: 9:05am | F37: 10:20am | G37: Client call | H37: =IF(ISNUMBER(MATCH(LOWER(TRIM(C37)),'Sample Mapping'!$A$5:$A$42,0)),"Yes","No") -> Yes | I37: Valid | J37: =IF(E37="",0,LEN(E37)-LEN(SUBSTITUTE(E37,CHAR(10),""))+1) -> 1
A38: S-104 | B38: Kiran Bhat | C38: kiran.bhat@example.com | D38: 10/20/2025 | G38: Will share exact times later | H38: =IF(ISNUMBER(MATCH(LOWER(TRIM(C38)),'Sample Mapping'!$A$5:$A$42,0)),"Yes","No") -> Yes | I38: Excluded: comments only | J38: =IF(E38="",0,LEN(E38)-LEN(SUBSTITUTE(E38,CHAR(10),""))+1) -> 0
A39: S-104 | B39: Leela Hughes | C39: leela.hughes@example.com | D39: 10/20/2025 | E39: 13:00 | G39: End time not noted | H39: =IF(ISNUMBER(MATCH(LOWER(TRIM(C39)),'Sample Mapping'!$A$5:$A$42,0)),"Yes","No") -> Yes | I39: Excluded: end time missing | J39: =IF(E39="",0,LEN(E39)-LEN(SUBSTITUTE(E39,CHAR(10),""))+1) -> 1
A40: S-104 | B40: Excluded User 2 | C40: excluded.user2@example.com | D40: 10/21/2025 | E40: 10:00 | F40: 10:30 | H40: =IF(ISNUMBER(MATCH(LOWER(TRIM(C40)),'Sample Mapping'!$A$5:$A$42,0)),"Yes","No") -> No | I40: Excluded: on exclusion list | J40: =IF(E40="",0,LEN(E40)-LEN(SUBSTITUTE(E40,CHAR(10),""))+1) -> 1
A41: S-104 | B41: Faisal Hassan | C41: faisal.hassan@example.com | D41: 10/21/2025 | E41: 1:45pm | F41: 2:25pm | G41: Laptop issue | H41: =IF(ISNUMBER(MATCH(LOWER(TRIM(C41)),'Sample Mapping'!$A$5:$A$42,0)),"Yes","No") -> Yes | I41: Valid | J41: =IF(E41="",0,LEN(E41)-LEN(SUBSTITUTE(E41,CHAR(10),""))+1) -> 1
...

Sheet Processed Instances
A1: Processed missed-time instances (one row per missed period)
A2: Output of validation, mapping and normalization; the analysis sheets read from this table.
A4: Session ID | B4: Learner Name | C4: Learner Email | D4: User ID | E4: Date | F4: Start Time | G4: End Time | H4: Program | I4: Session Day # | J4: Duration (min) | K4: Start Hour
A5: S-101 | B5: Ben Carter | C5: ben.carter@example.com | D5: =INDEX('Sample Mapping'!$B$5:$B$42,MATCH(C5,'Sample Mapping'!$A$5:$A$42,0)) -> U1002 | E5: 45936 | F5: 0.40277778 | G5: 0.41319444 | H5: =INDEX(Sessions!$B$5:$B$8,MATCH(A5,Sessions!$A$5:$A$8,0)) -> 1-Day Workshop | I5: =E5-INDEX(Sessions!$D$5:$D$8,MATCH(A5,Sessions!$A$5:$A$8,0))+1 -> 1 | J5: =ROUND((G5-F5)*1440,0) -> 15 | K5: =HOUR(F5) -> 9
A6: S-101 | B6: Ben Carter | C6: ben.carter@example.com | D6: =INDEX('Sample Mapping'!$B$5:$B$42,MATCH(C6,'Sample Mapping'!$A$5:$A$42,0)) -> U1002 | E6: 45936 | F6: 0.45833333 | G6: 0.51041667 | H6: =INDEX(Sessions!$B$5:$B$8,MATCH(A6,Sessions!$A$5:$A$8,0)) -> 1-Day Workshop | I6: =E6-INDEX(Sessions!$D$5:$D$8,MATCH(A6,Sessions!$A$5:$A$8,0))+1 -> 1 | J6: =ROUND((G6-F6)*1440,0) -> 75 | K6: =HOUR(F6) -> 11
A7: S-101 | B7: Dev Patel | C7: dev.patel@example.com | D7: =INDEX('Sample Mapping'!$B$5:$B$42,MATCH(C7,'Sample Mapping'!$A$5:$A$42,0)) -> U1004 | E7: 45936 | F7: 0.40625 | G7: 0.41666667 | H7: =INDEX(Sessions!$B$5:$B$8,MATCH(A7,Sessions!$A$5:$A$8,0)) -> 1-Day Workshop | I7: =E7-INDEX(Sessions!$D$5:$D$8,MATCH(A7,Sessions!$A$5:$A$8,0))+1 -> 1 | J7: =ROUND((G7-F7)*1440,0) -> 15 | K7: =HOUR(F7) -> 9
A8: S-101 | B8: Jon Brooks | C8: jon.brooks@example.com | D8: =INDEX('Sample Mapping'!$B$5:$B$42,MATCH(C8,'Sample Mapping'!$A$5:$A$42,0)) -> U1009 | E8: 45936 | F8: 0.42361111 | G8: 0.47569444 | H8: =INDEX(Sessions!$B$5:$B$8,MATCH(A8,Sessions!$A$5:$A$8,0)) -> 1-Day Workshop | I8: =E8-INDEX(Sessions!$D$5:$D$8,MATCH(A8,Sessions!$A$5:$A$8,0))+1 -> 1 | J8: =ROUND((G8-F8)*1440,0) -> 75 | K8: =HOUR(F8) -> 10
A9: S-101 | B9: Jon Brooks | C9: jon.brooks@example.com | D9: =INDEX('Sample Mapping'!$B$5:$B$42,MATCH(C9,'Sample Mapping'!$A$5:$A$42,0)) -> U1009 | E9: 45936 | F9: 0.63194444 | G9: 0.64236111 | H9: =INDEX(Sessions!$B$5:$B$8,MATCH(A9,Sessions!$A$5:$A$8,0)) -> 1-Day Workshop | I9: =E9-INDEX(Sessions!$D$5:$D$8,MATCH(A9,Sessions!$A$5:$A$8,0))+1 -> 1 | J9: =ROUND((G9-F9)*1440,0) -> 15 | K9: =HOUR(F9) -> 15
A10: S-102 | B10: Tariq Ali | C10: tariq.ali@example.com | D10: =INDEX('Sample Mapping'!$B$5:$B$42,MATCH(C10,'Sample Mapping'!$A$5:$A$42,0)) -> U1018 | E10: 45937 | F10: 0.4375 | G10: 0.46527778 | H10: =INDEX(Sessions!$B$5:$B$8,MATCH(A10,Sessions!$A$5:$A$8,0)) -> 2-Day Bootcamp | I10: =E10-INDEX(Sessions!$D$5:$D$8,MATCH(A10,Sessions!$A$5:$A$8,0))+1 -> 1 | J10: =ROUND((G10-F10)*1440,0) -> 40 | K10: =HOUR(F10) -> 10
A11: S-102 | B11: Tariq Ali | C11: tariq.ali@example.com | D11: =INDEX('Sample Mapping'!$B$5:$B$42,MATCH(C11,'Sample Mapping'!$A$5:$A$42,0)) -> U1018 | E11: 45937 | F11: 0.61805556 | G11: 0.65972222 | H11: =INDEX(Sessions!$B$5:$B$8,MATCH(A11,Sessions!$A$5:$A$8,0)) -> 2-Day Bootcamp | I11: =E11-INDEX(Sessions!$D$5:$D$8,MATCH(A11,Sessions!$A$5:$A$8,0))+1 -> 1 | J11: =ROUND((G11-F11)*1440,0) -> 60 | K11: =HOUR(F11) -> 14
A12: S-102 | B12: Liam Murphy | C12: liam.murphy@example.com | D12: =INDEX('Sample Mapping'!$B$5:$B$42,MATCH(C12,'Sample Mapping'!$A$5:$A$42,0)) -> U1011 | E12: 45938 | F12: 0.45138889 | G12: 0.50347222 | H12: =INDEX(Sessions!$B$5:$B$8,MATCH(A12,Sessions!$A$5:$A$8,0)) -> 2-Day Bootcamp | I12: =E12-INDEX(Sessions!$D$5:$D$8,MATCH(A12,Sessions!$A$5:$A$8,0))+1 -> 2 | J12: =ROUND((G12-F12)*1440,0) -> 75 | K12: =HOUR(F12) -> 10
A13: S-102 | B13: Olivia Reed | C13: olivia.reed@example.com | D13: =INDEX('Sample Mapping'!$B$5:$B$42,MATCH(C13,'Sample Mapping'!$A$5:$A$42,0)) -> U1014 | E13: 45938 | F13: 0.55902778 | G13: 0.60069444 | H13: =INDEX(Sessions!$B$5:$B$8,MATCH(A13,Sessions!$A$5:$A$8,0)) -> 2-Day Bootcamp | I13: =E13-INDEX(Sessions!$D$5:$D$8,MATCH(A13,Sessions!$A$5:$A$8,0))+1 -> 2 | J13: =ROUND((G13-F13)*1440,0) -> 60 | K13: =HOUR(F13) -> 13
A14: S-102 | B14: Tariq Ali | C14: tariq.ali@example.com | D14: =INDEX('Sample Mapping'!$B$5:$B$42,MATCH(C14,'Sample Mapping'!$A$5:$A$42,0)) -> U1018 | E14: 45938 | F14: 0.38888889 | G14: 0.40277778 | H14: =INDEX(Sessions!$B$5:$B$8,MATCH(A14,Sessions!$A$5:$A$8,0)) -> 2-Day Bootcamp | I14: =E14-INDEX(Sessions!$D$5:$D$8,MATCH(A14,Sessions!$A$5:$A$8,0))+1 -> 2 | J14: =ROUND((G14-F14)*1440,0) -> 20 | K14: =HOUR(F14) -> 9
A15: S-103 | B15: Bianca Silva | C15: bianca.silva@example.com | D15: =INDEX('Sample Mapping'!$B$5:$B$42,MATCH(C15,'Sample Mapping'!$A$5:$A$42,0)) -> U1026 | E15: 45943 | F15: 0.58333333 | G15: 0.60416667 | H15: =INDEX(Sessions!$B$5:$B$8,MATCH(A15,Sessions!$A$5:$A$8,0)) -> 4-Day Program | I15: =E15-INDEX(Sessions!$D$5:$D$8,MATCH(A15,Sessions!$A$5:$A$8,0))+1 -> 1 | J15: =ROUND((G15-F15)*1440,0) -> 30 | K15: =HOUR(F15) -> 14
A16: S-103 | B16: Elena Ortiz | C16: elena.ortiz@example.com | D16: =INDEX('Sample Mapping'!$B$5:$B$42,MATCH(C16,'Sample Mapping'!$A$5:$A$42,0)) -> U1029 | E16: 45943 | F16: 0.54861111 | G16: 0.57986111 | H16: =INDEX(Sessions!$B$5:$B$8,MATCH(A16,Sessions!$A$5:$A$8,0)) -> 4-Day Program | I16: =E16-INDEX(Sessions!$D$5:$D$8,MATCH(A16,Sessions!$A$5:$A$8,0))+1 -> 1 | J16: =ROUND((G16-F16)*1440,0) -> 45 | K16: =HOUR(F16) -> 13
... A63: S-104 | B63: Omar Pillai | C63: omar.pillai@example.com | D63: =INDEX('Sample Mapping'!$B$5:$B$42,MATCH(C63,'Sample Mapping'!$A$5:$A$42,0)) -> U1038 | E63: 45954 | F63: 0.58680556 | G63: 0.63888889 | H63: =INDEX(Sessions!$B$5:$B$8,MATCH(A63,Sessions!$A$5:$A$8,0)) -> 5-Day Academy | I63: =E63-INDEX(Sessions!$D$5:$D$8,MATCH(A63,Sessions!$A$5:$A$8,0))+1 -> 5 | J63: =ROUND((G63-F63)*1440,0) -> 75 | K63: =HOUR(F63) -> 14

Sheet Sample Output
A1: Sample output: populated Missed Time template (upload-ready)
A2: User ID, Session Learning Object ID (sample placeholder, looked up from the Learner Roster) and the two missed time columns.
A4: User ID | B4: Session Learning Object ID | C4: Missed Start Time | D4: Missed End Time
A5: U1002 | B5: =INDEX('Learner Roster'!$E$5:$E$44,MATCH(A5,'Learner Roster'!$C$5:$C$44,0)) -> SLO-6VTHIB2TN9QJ3U3LQ2QY1UXV | C5: 10/06/2025 09:40 | D5: 10/06/2025 09:55
A6: U1002 | B6: =INDEX('Learner Roster'!$E$5:$E$44,MATCH(A6,'Learner Roster'!$C$5:$C$44,0)) -> SLO-6VTHIB2TN9QJ3U3LQ2QY1UXV | C6: 10/06/2025 11:00 | D6: 10/06/2025 12:15
A7: U1004 | B7: =INDEX('Learner Roster'!$E$5:$E$44,MATCH(A7,'Learner Roster'!$C$5:$C$44,0)) -> SLO-SUYHHFPU1JAUHFGY0J6E | C7: 10/06/2025 09:45 | D7: 10/06/2025 10:00
A8: U1009 | B8: =INDEX('Learner Roster'!$E$5:$E$44,MATCH(A8,'Learner Roster'!$C$5:$C$44,0)) -> SLO-ERZ1KJAAZKPG06TVX4F3JX | C8: 10/06/2025 10:10 | D8: 10/06/2025 11:25
A9: U1009 | B9: =INDEX('Learner Roster'!$E$5:$E$44,MATCH(A9,'Learner Roster'!$C$5:$C$44,0)) -> SLO-ERZ1KJAAZKPG06TVX4F3JX | C9: 10/06/2025 15:10 | D9: 10/06/2025 15:25
A10: U1018 | B10: =INDEX('Learner Roster'!$E$5:$E$44,MATCH(A10,'Learner Roster'!$C$5:$C$44,0)) -> SLO-4XB54CJ6QBM2ZEIO7OT9OTG | C10: 10/07/2025 10:30 | D10: 10/07/2025 11:10
A11: U1018 | B11: =INDEX('Learner Roster'!$E$5:$E$44,MATCH(A11,'Learner Roster'!$C$5:$C$44,0)) -> SLO-4XB54CJ6QBM2ZEIO7OT9OTG | C11: 10/07/2025 14:50 | D11: 10/07/2025 15:50
A12: U1011 | B12: =INDEX('Learner Roster'!$E$5:$E$44,MATCH(A12,'Learner Roster'!$C$5:$C$44,0)) -> SLO-AMFK2A87YFF1W7DB19FE1 | C12: 10/08/2025 10:50 | D12: 10/08/2025 12:05
A13: U1014 | B13: =INDEX('Learner Roster'!$E$5:$E$44,MATCH(A13,'Learner Roster'!$C$5:$C$44,0)) -> SLO-L8Q660HBXTS5W66JWE7ZVB | C13: 10/08/2025 13:25 | D13: 10/08/2025 14:25
A14: U1018 | B14: =INDEX('Learner Roster'!$E$5:$E$44,MATCH(A14,'Learner Roster'!$C$5:$C$44,0)) -> SLO-4XB54CJ6QBM2ZEIO7OT9OTG | C14: 10/08/2025 09:20 | D14: 10/08/2025 09:40
A15: U1026 | B15: =INDEX('Learner Roster'!$E$5:$E$44,MATCH(A15,'Learner Roster'!$C$5:$C$44,0)) -> SLO-OKUWGD9D4WDIPON5UK28 | C15: 10/13/2025 14:00 | D15: 10/13/2025 14:30
A16: U1029 | B16: =INDEX('Learner Roster'!$E$5:$E$44,MATCH(A16,'Learner Roster'!$C$5:$C$44,0)) -> SLO-QIJ3GVGQ8ST8FRF136RYXL9L | C16: 10/13/2025 13:10 | D16: 10/13/2025 13:55
... A63: U1038 | B63: =INDEX('Learner Roster'!$E$5:$E$44,MATCH(A63,'Learner Roster'!$C$5:$C$44,0)) -> SLO-VSIXVAUKOVQNW8DCCEIGKHY | C63: 10/24/2025 14:05 | D63: 10/24/2025 15:20

Sheet Validation Report
A1: Validation report (grouped by learner)
A2: Missed times merged chronologically as comma-separated values
A4: Measure | B4: Value
A5: Total learners processed | B5: =COUNTA(A11:A33) -> 23
A6: Total missed instances identified | B6: =SUM(H11:H33) -> 59
A7: Learners with multiple missed occurrences | B7: =COUNTIF(H11:H33,">1") -> 14
A8: Max instances for one learner | B8: =MAX(H11:H33) -> 8
A10: Learner Name | B10: Learner Email | C10: User ID | D10: Session ID | E10: Program | F10: Missed Start Times | G10: Missed End Times | H10: Missed Instance Count | I10: Total Missed Minutes
A11: Ben Carter | B11: ben.carter@example.com | C11: U1002 | D11: S-101 | E11: =INDEX(Sessions!$B$5:$B$8,MATCH(D11,Sessions!$A$5:$A$8,0)) -> 1-Day Workshop | F11: 10/06/2025 09:40, 10/06/2025 11:00 | G11: 10/06/2025 09:55, 10/06/2025 12:15 | H11: =COUNTIF('Processed Instances'!$C$5:$C$63,B11) -> 2 | I11: =SUMIF('Processed Instances'!$C$5:$C$63,B11,'Processed Instances'!$J$5:$J$63) -> 90
A12: Dev Patel | B12: dev.patel@example.com | C12: U1004 | D12: S-101 | E12: =INDEX(Sessions!$B$5:$B$8,MATCH(D12,Sessions!$A$5:$A$8,0)) -> 1-Day Workshop | F12: 10/06/2025 09:45 | G12: 10/06/2025 10:00 | H12: =COUNTIF('Processed Instances'!$C$5:$C$63,B12) -> 1 | I12: =SUMIF('Processed Instances'!$C$5:$C$63,B12,'Processed Instances'!$J$5:$J$63) -> 15
A13: Jon Brooks | B13: jon.brooks@example.com | C13: U1009 | D13: S-101 | E13: =INDEX(Sessions!$B$5:$B$8,MATCH(D13,Sessions!$A$5:$A$8,0)) -> 1-Day Workshop | F13: 10/06/2025 10:10, 10/06/2025 15:10 | G13: 10/06/2025 11:25, 10/06/2025 15:25 | H13: =COUNTIF('Processed Instances'!$C$5:$C$63,B13) -> 2 | I13: =SUMIF('Processed Instances'!$C$5:$C$63,B13,'Processed Instances'!$J$5:$J$63) -> 90
A14: Liam Murphy | B14: liam.murphy@example.com | C14: U1011 | D14: S-102 | E14: =INDEX(Sessions!$B$5:$B$8,MATCH(D14,Sessions!$A$5:$A$8,0)) -> 2-Day Bootcamp | F14: 10/08/2025 10:50 | G14: 10/08/2025 12:05 | H14: =COUNTIF('Processed Instances'!$C$5:$C$63,B14) -> 1 | I14: =SUMIF('Processed Instances'!$C$5:$C$63,B14,'Processed Instances'!$J$5:$J$63) -> 75
A15: Olivia Reed | B15: olivia.reed@example.com | C15: U1014 | D15: S-102 | E15: =INDEX(Sessions!$B$5:$B$8,MATCH(D15,Sessions!$A$5:$A$8,0)) -> 2-Day Bootcamp | F15: 10/08/2025 13:25 | G15: 10/08/2025 14:25 | H15: =COUNTIF('Processed Instances'!$C$5:$C$63,B15) -> 1 | I15: =SUMIF('Processed Instances'!$C$5:$C$63,B15,'Processed Instances'!$J$5:$J$63) -> 60
A16: Tariq Ali | B16: tariq.ali@example.com | C16: U1018 | D16: S-102 | E16: =INDEX(Sessions!$B$5:$B$8,MATCH(D16,Sessions!$A$5:$A$8,0)) -> 2-Day Bootcamp | F16: 10/07/2025 10:30, 10/07/2025 14:50, 10/08/2025 09:20 | G16: 10/07/2025 11:10, 10/07/2025 15:50, 10/08/2025 09:40 | H16: =COUNTIF('Processed Instances'!$C$5:$C$63,B16) -> 3 | I16: =SUMIF('Processed Instances'!$C$5:$C$63,B16,'Processed Instances'!$J$5:$J$63) -> 120
A17: Anil Verma | B17: anil.verma@example.com | C17: U1025 | D17: S-103 | E17: =INDEX(Sessions!$B$5:$B$8,MATCH(D17,Sessions!$A$5:$A$8,0)) -> 4-Day Program | F17: 10/15/2025 11:55, 10/15/2025 13:10, 10/15/2025 15:40, 10/16/2025 15:15 | G17: 10/15/2025 13:10, 10/15/2025 13:50, 10/15/2025 16:10, 10/16/2025 15:40 | H17: =COUNTIF('Processed Instances'!$C$5:$C$63,B17) -> 4 | I17: =SUMIF('Processed Instances'!$C$5:$C$63,B17,'Processed Instances'!$J$5:$J$63) -> 170
A18: Bianca Silva | B18: bianca.silva@example.com | C18: U1026 | D18: S-103 | E18: =INDEX(Sessions!$B$5:$B$8,MATCH(D18,Sessions!$A$5:$A$8,0)) -> 4-Day Program | F18: 10/13/2025 14:00 | G18: 10/13/2025 14:30 | H18: =COUNTIF('Processed Instances'!$C$5:$C$63,B18) -> 1 | I18: =SUMIF('Processed Instances'!$C$5:$C$63,B18,'Processed Instances'!$J$5:$J$63) -> 30
A19: Carlos Nguyen | B19: carlos.nguyen@example.com | C19: U1027 | D19: S-103 | E19: =INDEX(Sessions!$B$5:$B$8,MATCH(D19,Sessions!$A$5:$A$8,0)) -> 4-Day Program | F19: 10/16/2025 10:15 | G19: 10/16/2025 11:15 | H19: =COUNTIF('Processed Instances'!$C$5:$C$63,B19) -> 1 | I19: =SUMIF('Processed Instances'!$C$5:$C$63,B19,'Processed Instances'!$J$5:$J$63) -> 60
A20: Elena Ortiz | B20: elena.ortiz@example.com | C20: U1029 | D20: S-103 | E20: =INDEX(Sessions!$B$5:$B$8,MATCH(D20,Sessions!$A$5:$A$8,0)) -> 4-Day Program | F20: 10/13/2025 13:10, 10/13/2025 15:55, 10/16/2025 16:00 | G20: 10/13/2025 13:55, 10/13/2025 16:20, 10/16/2025 16:20 | H20: =COUNTIF('Processed Instances'!$C$5:$C$63,B20) -> 3 | I20: =SUMIF('Processed Instances'!$C$5:$C$63,B20,'Processed Instances'!$J$5:$J$63) -> 90
A21: Vikram Bose | B21: vikram.bose@example.com | C21: U1020 | D21: S-103 | E21: =INDEX(Sessions!$B$5:$B$8,MATCH(D21,Sessions!$A$5:$A$8,0)) -> 4-Day Program | F21: 10/13/2025 10:10, 10/16/2025 09:10 | G21: 10/13/2025 10:55, 10/16/2025 09:35 | H21: =COUNTIF('Processed Instances'!$C$5:$C$63,B21) -> 2 | I21: =SUMIF('Processed Instances'!$C$5:$C$63,B21,'Processed Instances'!$J$5:$J$63) -> 70
A22: Wen Chen | B22: wen.chen@example.com | C22: U1021 | D22: S-103 | E22: =INDEX(Sessions!$B$5:$B$8,MATCH(D22,Sessions!$A$5:$A$8,0)) -> 4-Day Program | F22: 10/14/2025 09:40 | G22: 10/14/2025 10:20 | H22: =COUNTIF('Processed Instances'!$C$5:$C$63,B22) -> 1 | I22: =SUMIF('Processed Instances'!$C$5:$C$63,B22,'Processed Instances'!$J$5:$J$63) -> 40
... A33: Omar Pillai | B33: omar.pillai@example.com | C33: U1038 | D33: S-104 | E33: =INDEX(Sessions!$B$5:$B$8,MATCH(D33,Sessions!$A$5:$A$8,0)) -> 5-Day Academy | F33: 10/21/2025 10:00, 10/22/2025 15:15, 10/23/2025 14:15, 10/24/2025 11:20, 10/24/2025 14:05 | G33: 10/21/2025 10:30, 10/22/2025 15:55, 10/23/2025 15:30, 10/24/2025 11:50, 10/24/2025 15:20 | H33: =COUNTIF('Processed Instances'!$C$5:$C$63,B33) -> 5 | I33: =SUMIF('Processed Instances'!$C$5:$C$63,B33,'Processed Instances'!$J$5:$J$63) -> 250

Sheet Daily Breakdown
A1: Daily breakdown: missed time for each day separately
A2: One row per learner per session day. Times within a day are comma-separated and in upload format (MM/DD/YYYY HH:MM).
A4: Learner Name | B4: Learner Email | C4: User ID | D4: Session ID | E4: Program | F4: Date | G4: Day # | H4: Missed Time Start | I4: Missed Time End | J4: Missed periods | K4: Missed minutes
A5: Ben Carter | B5: ben.carter@example.com | C5: U1002 | D5: S-101 | E5: =INDEX(Sessions!$B$5:$B$8,MATCH(D5,Sessions!$A$5:$A$8,0)) -> 1-Day Workshop | F5: 45936 | G5: =F5-INDEX(Sessions!$D$5:$D$8,MATCH(D5,Sessions!$A$5:$A$8,0))+1 -> 1 | H5: 10/06/2025 09:40, 10/06/2025 11:00 | I5: 10/06/2025 09:55, 10/06/2025 12:15 | J5: =COUNTIFS('Processed Instances'!$C$5:$C$63,B5,'Processed Instances'!$E$5:$E$63,F5) -> 2 | K5: =SUMIFS('Processed Instances'!$J$5:$J$63,'Processed Instances'!$C$5:$C$63,B5,'Processed Instances'!$E$5:$E$63,F5) -> 90
A6: Dev Patel | B6: dev.patel@example.com | C6: U1004 | D6: S-101 | E6: =INDEX(Sessions!$B$5:$B$8,MATCH(D6,Sessions!$A$5:$A$8,0)) -> 1-Day Workshop | F6: 45936 | G6: =F6-INDEX(Sessions!$D$5:$D$8,MATCH(D6,Sessions!$A$5:$A$8,0))+1 -> 1 | H6: 10/06/2025 09:45 | I6: 10/06/2025 10:00 | J6: =COUNTIFS('Processed Instances'!$C$5:$C$63,B6,'Processed Instances'!$E$5:$E$63,F6) -> 1 | K6: =SUMIFS('Processed Instances'!$J$5:$J$63,'Processed Instances'!$C$5:$C$63,B6,'Processed Instances'!$E$5:$E$63,F6) -> 15
A7: Jon Brooks | B7: jon.brooks@example.com | C7: U1009 | D7: S-101 | E7: =INDEX(Sessions!$B$5:$B$8,MATCH(D7,Sessions!$A$5:$A$8,0)) -> 1-Day Workshop | F7: 45936 | G7: =F7-INDEX(Sessions!$D$5:$D$8,MATCH(D7,Sessions!$A$5:$A$8,0))+1 -> 1 | H7: 10/06/2025 10:10, 10/06/2025 15:10 | I7: 10/06/2025 11:25, 10/06/2025 15:25 | J7: =COUNTIFS('Processed Instances'!$C$5:$C$63,B7,'Processed Instances'!$E$5:$E$63,F7) -> 2 | K7: =SUMIFS('Processed Instances'!$J$5:$J$63,'Processed Instances'!$C$5:$C$63,B7,'Processed Instances'!$E$5:$E$63,F7) -> 90
A8: Liam Murphy | B8: liam.murphy@example.com | C8: U1011 | D8: S-102 | E8: =INDEX(Sessions!$B$5:$B$8,MATCH(D8,Sessions!$A$5:$A$8,0)) -> 2-Day Bootcamp | F8: 45938 | G8: =F8-INDEX(Sessions!$D$5:$D$8,MATCH(D8,Sessions!$A$5:$A$8,0))+1 -> 2 | H8: 10/08/2025 10:50 | I8: 10/08/2025 12:05 | J8: =COUNTIFS('Processed Instances'!$C$5:$C$63,B8,'Processed Instances'!$E$5:$E$63,F8) -> 1 | K8: =SUMIFS('Processed Instances'!$J$5:$J$63,'Processed Instances'!$C$5:$C$63,B8,'Processed Instances'!$E$5:$E$63,F8) -> 75
A9: Olivia Reed | B9: olivia.reed@example.com | C9: U1014 | D9: S-102 | E9: =INDEX(Sessions!$B$5:$B$8,MATCH(D9,Sessions!$A$5:$A$8,0)) -> 2-Day Bootcamp | F9: 45938 | G9: =F9-INDEX(Sessions!$D$5:$D$8,MATCH(D9,Sessions!$A$5:$A$8,0))+1 -> 2 | H9: 10/08/2025 13:25 | I9: 10/08/2025 14:25 | J9: =COUNTIFS('Processed Instances'!$C$5:$C$63,B9,'Processed Instances'!$E$5:$E$63,F9) -> 1 | K9: =SUMIFS('Processed Instances'!$J$5:$J$63,'Processed Instances'!$C$5:$C$63,B9,'Processed Instances'!$E$5:$E$63,F9) -> 60
A10: Tariq Ali | B10: tariq.ali@example.com | C10: U1018 | D10: S-102 | E10: =INDEX(Sessions!$B$5:$B$8,MATCH(D10,Sessions!$A$5:$A$8,0)) -> 2-Day Bootcamp | F10: 45937 | G10: =F10-INDEX(Sessions!$D$5:$D$8,MATCH(D10,Sessions!$A$5:$A$8,0))+1 -> 1 | H10: 10/07/2025 10:30, 10/07/2025 14:50 | I10: 10/07/2025 11:10, 10/07/2025 15:50 | J10: =COUNTIFS('Processed Instances'!$C$5:$C$63,B10,'Processed Instances'!$E$5:$E$63,F10) -> 2 | K10: =SUMIFS('Processed Instances'!$J$5:$J$63,'Processed Instances'!$C$5:$C$63,B10,'Processed Instances'!$E$5:$E$63,F10) -> 100
A11: Tariq Ali | B11: tariq.ali@example.com | C11: U1018 | D11: S-102 | E11: =INDEX(Sessions!$B$5:$B$8,MATCH(D11,Sessions!$A$5:$A$8,0)) -> 2-Day Bootcamp | F11: 45938 | G11: =F11-INDEX(Sessions!$D$5:$D$8,MATCH(D11,Sessions!$A$5:$A$8,0))+1 -> 2 | H11: 10/08/2025 09:20 | I11: 10/08/2025 09:40 | J11: =COUNTIFS('Processed Instances'!$C$5:$C$63,B11,'Processed Instances'!$E$5:$E$63,F11) -> 1 | K11: =SUMIFS('Processed Instances'!$J$5:$J$63,'Processed Instances'!$C$5:$C$63,B11,'Processed Instances'!$E$5:$E$63,F11) -> 20
A12: Anil Verma | B12: anil.verma@example.com | C12: U1025 | D12: S-103 | E12: =INDEX(Sessions!$B$5:$B$8,MATCH(D12,Sessions!$A$5:$A$8,0)) -> 4-Day Program | F12: 45945 | G12: =F12-INDEX(Sessions!$D$5:$D$8,MATCH(D12,Sessions!$A$5:$A$8,0))+1 -> 3 | H12: 10/15/2025 11:55, 10/15/2025 13:10, 10/15/2025 15:40 | I12: 10/15/2025 13:10, 10/15/2025 13:50, 10/15/2025 16:10 | J12: =COUNTIFS('Processed Instances'!$C$5:$C$63,B12,'Processed Instances'!$E$5:$E$63,F12) -> 3 | K12: =SUMIFS('Processed Instances'!$J$5:$J$63,'Processed Instances'!$C$5:$C$63,B12,'Processed Instances'!$E$5:$E$63,F12) -> 145
A13: Anil Verma | B13: anil.verma@example.com | C13: U1025 | D13: S-103 | E13: =INDEX(Sessions!$B$5:$B$8,MATCH(D13,Sessions!$A$5:$A$8,0)) -> 4-Day Program | F13: 45946 | G13: =F13-INDEX(Sessions!$D$5:$D$8,MATCH(D13,Sessions!$A$5:$A$8,0))+1 -> 4 | H13: 10/16/2025 15:15 | I13: 10/16/2025 15:40 | J13: =COUNTIFS('Processed Instances'!$C$5:$C$63,B13,'Processed Instances'!$E$5:$E$63,F13) -> 1 | K13: =SUMIFS('Processed Instances'!$J$5:$J$63,'Processed Instances'!$C$5:$C$63,B13,'Processed Instances'!$E$5:$E$63,F13) -> 25
A14: Bianca Silva | B14: bianca.silva@example.com | C14: U1026 | D14: S-103 | E14: =INDEX(Sessions!$B$5:$B$8,MATCH(D14,Sessions!$A$5:$A$8,0)) -> 4-Day Program | F14: 45943 | G14: =F14-INDEX(Sessions!$D$5:$D$8,MATCH(D14,Sessions!$A$5:$A$8,0))+1 -> 1 | H14: 10/13/2025 14:00 | I14: 10/13/2025 14:30 | J14: =COUNTIFS('Processed Instances'!$C$5:$C$63,B14,'Processed Instances'!$E$5:$E$63,F14) -> 1 | K14: =SUMIFS('Processed Instances'!$J$5:$J$63,'Processed Instances'!$C$5:$C$63,B14,'Processed Instances'!$E$5:$E$63,F14) -> 30
A15: Carlos Nguyen | B15: carlos.nguyen@example.com | C15: U1027 | D15: S-103 | E15: =INDEX(Sessions!$B$5:$B$8,MATCH(D15,Sessions!$A$5:$A$8,0)) -> 4-Day Program | F15: 45946 | G15: =F15-INDEX(Sessions!$D$5:$D$8,MATCH(D15,Sessions!$A$5:$A$8,0))+1 -> 4 | H15: 10/16/2025 10:15 | I15: 10/16/2025 11:15 | J15: =COUNTIFS('Processed Instances'!$C$5:$C$63,B15,'Processed Instances'!$E$5:$E$63,F15) -> 1 | K15: =SUMIFS('Processed Instances'!$J$5:$J$63,'Processed Instances'!$C$5:$C$63,B15,'Processed Instances'!$E$5:$E$63,F15) -> 60
A16: Elena Ortiz | B16: elena.ortiz@example.com | C16: U1029 | D16: S-103 | E16: =INDEX(Sessions!$B$5:$B$8,MATCH(D16,Sessions!$A$5:$A$8,0)) -> 4-Day Program | F16: 45943 | G16: =F16-INDEX(Sessions!$D$5:$D$8,MATCH(D16,Sessions!$A$5:$A$8,0))+1 -> 1 | H16: 10/13/2025 13:10, 10/13/2025 15:55 | I16: 10/13/2025 13:55, 10/13/2025 16:20 | J16: =COUNTIFS('Processed Instances'!$C$5:$C$63,B16,'Processed Instances'!$E$5:$E$63,F16) -> 2 | K16: =SUMIFS('Processed Instances'!$J$5:$J$63,'Processed Instances'!$C$5:$C$63,B16,'Processed Instances'!$E$5:$E$63,F16) -> 70
... A42: Omar Pillai | B42: omar.pillai@example.com | C42: U1038 | D42: S-104 | E42: =INDEX(Sessions!$B$5:$B$8,MATCH(D42,Sessions!$A$5:$A$8,0)) -> 5-Day Academy | F42: 45954 | G42: =F42-INDEX(Sessions!$D$5:$D$8,MATCH(D42,Sessions!$A$5:$A$8,0))+1 -> 5 | H42: 10/24/2025 11:20, 10/24/2025 14:05 | I42: 10/24/2025 11:50, 10/24/2025 15:20 | J42: =COUNTIFS('Processed Instances'!$C$5:$C$63,B42,'Processed Instances'!$E$5:$E$63,F42) -> 2 | K42: =SUMIFS('Processed Instances'!$J$5:$J$63,'Processed Instances'!$C$5:$C$63,B42,'Processed Instances'!$E$5:$E$63,F42) -> 105

Sheet Daily Matrix
A1: Daily matrix: missed start and end time for every day, side by side
A2: Times shown as HH:MM. A dash means no missed time that day; grey cells are days outside the learner's program.
A4: Learner Name | B4: Session ID | C4: Program | D4: Day 1 Start | E4: Day 1 End | F4: Day 2 Start | G4: Day 2 End | H4: Day 3 Start | I4: Day 3 End | J4: Day 4 Start | K4: Day 4 End | L4: Day 5 Start | M4: Day 5 End | N4: Total instances | O4: Total minutes
A5: Ben Carter | B5: S-101 | C5: =INDEX(Sessions!$B$5:$B$8,MATCH(B5,Sessions!$A$5:$A$8,0)) -> 1-Day Workshop | D5: 09:40, 11:00 | E5: 09:55, 12:15 | N5: =COUNTIF('Processed Instances'!$B$5:$B$63,A5) -> 2 | O5: =SUMIF('Processed Instances'!$B$5:$B$63,A5,'Processed Instances'!$J$5:$J$63) -> 90
A6: Dev Patel | B6: S-101 | C6: =INDEX(Sessions!$B$5:$B$8,MATCH(B6,Sessions!$A$5:$A$8,0)) -> 1-Day Workshop | D6: 09:45 | E6: 10:00 | N6: =COUNTIF('Processed Instances'!$B$5:$B$63,A6) -> 1 | O6: =SUMIF('Processed Instances'!$B$5:$B$63,A6,'Processed Instances'!$J$5:$J$63) -> 15
A7: Jon Brooks | B7: S-101 | C7: =INDEX(Sessions!$B$5:$B$8,MATCH(B7,Sessions!$A$5:$A$8,0)) -> 1-Day Workshop | D7: 10:10, 15:10 | E7: 11:25, 15:25 | N7: =COUNTIF('Processed Instances'!$B$5:$B$63,A7) -> 2 | O7: =SUMIF('Processed Instances'!$B$5:$B$63,A7,'Processed Instances'!$J$5:$J$63) -> 90
A8: Liam Murphy | B8: S-102 | C8: =INDEX(Sessions!$B$5:$B$8,MATCH(B8,Sessions!$A$5:$A$8,0)) -> 2-Day Bootcamp | D8: – | E8: – | F8: 10:50 | G8: 12:05 | N8: =COUNTIF('Processed Instances'!$B$5:$B$63,A8) -> 1 | O8: =SUMIF('Processed Instances'!$B$5:$B$63,A8,'Processed Instances'!$J$5:$J$63) -> 75
A9: Olivia Reed | B9: S-102 | C9: =INDEX(Sessions!$B$5:$B$8,MATCH(B9,Sessions!$A$5:$A$8,0)) -> 2-Day Bootcamp | D9: – | E9: – | F9: 13:25 | G9: 14:25 | N9: =COUNTIF('Processed Instances'!$B$5:$B$63,A9) -> 1 | O9: =SUMIF('Processed Instances'!$B$5:$B$63,A9,'Processed Instances'!$J$5:$J$63) -> 60
A10: Tariq Ali | B10: S-102 | C10: =INDEX(Sessions!$B$5:$B$8,MATCH(B10,Sessions!$A$5:$A$8,0)) -> 2-Day Bootcamp | D10: 10:30, 14:50 | E10: 11:10, 15:50 | F10: 09:20 | G10: 09:40 | N10: =COUNTIF('Processed Instances'!$B$5:$B$63,A10) -> 3 | O10: =SUMIF('Processed Instances'!$B$5:$B$63,A10,'Processed Instances'!$J$5:$J$63) -> 120
A11: Anil Verma | B11: S-103 | C11: =INDEX(Sessions!$B$5:$B$8,MATCH(B11,Sessions!$A$5:$A$8,0)) -> 4-Day Program | D11: – | E11: – | F11: – | G11: – | H11: 11:55, 13:10, 15:40 | I11: 13:10, 13:50, 16:10 | J11: 15:15 | K11: 15:40 | N11: =COUNTIF('Processed Instances'!$B$5:$B$63,A11) -> 4 | O11: =SUMIF('Processed Instances'!$B$5:$B$63,A11,'Processed Instances'!$J$5:$J$63) -> 170
A12: Bianca Silva | B12: S-103 | C12: =INDEX(Sessions!$B$5:$B$8,MATCH(B12,Sessions!$A$5:$A$8,0)) -> 4-Day Program | D12: 14:00 | E12: 14:30 | F12: – | G12: – | H12: – | I12: – | J12: – | K12: – | N12: =COUNTIF('Processed Instances'!$B$5:$B$63,A12) -> 1 | O12: =SUMIF('Processed Instances'!$B$5:$B$63,A12,'Processed Instances'!$J$5:$J$63) -> 30
A13: Carlos Nguyen | B13: S-103 | C13: =INDEX(Sessions!$B$5:$B$8,MATCH(B13,Sessions!$A$5:$A$8,0)) -> 4-Day Program | D13: – | E13: – | F13: – | G13: – | H13: – | I13: – | J13: 10:15 | K13: 11:15 | N13: =COUNTIF('Processed Instances'!$B$5:$B$63,A13) -> 1 | O13: =SUMIF('Processed Instances'!$B$5:$B$63,A13,'Processed Instances'!$J$5:$J$63) -> 60
A14: Elena Ortiz | B14: S-103 | C14: =INDEX(Sessions!$B$5:$B$8,MATCH(B14,Sessions!$A$5:$A$8,0)) -> 4-Day Program | D14: 13:10, 15:55 | E14: 13:55, 16:20 | F14: – | G14: – | H14: – | I14: – | J14: 16:00 | K14: 16:20 | N14: =COUNTIF('Processed Instances'!$B$5:$B$63,A14) -> 3 | O14: =SUMIF('Processed Instances'!$B$5:$B$63,A14,'Processed Instances'!$J$5:$J$63) -> 90
A15: Vikram Bose | B15: S-103 | C15: =INDEX(Sessions!$B$5:$B$8,MATCH(B15,Sessions!$A$5:$A$8,0)) -> 4-Day Program | D15: 10:10 | E15: 10:55 | F15: – | G15: – | H15: – | I15: – | J15: 09:10 | K15: 09:35 | N15: =COUNTIF('Processed Instances'!$B$5:$B$63,A15) -> 2 | O15: =SUMIF('Processed Instances'!$B$5:$B$63,A15,'Processed Instances'!$J$5:$J$63) -> 70
A16: Wen Chen | B16: S-103 | C16: =INDEX(Sessions!$B$5:$B$8,MATCH(B16,Sessions!$A$5:$A$8,0)) -> 4-Day Program | D16: – | E16: – | F16: 09:40 | G16: 10:20 | H16: – | I16: – | J16: – | K16: – | N16: =COUNTIF('Processed Instances'!$B$5:$B$63,A16) -> 1 | O16: =SUMIF('Processed Instances'!$B$5:$B$63,A16,'Processed Instances'!$J$5:$J$63) -> 40
A17: Xavier Fischer | B17: S-103 | C17: =INDEX(Sessions!$B$5:$B$8,MATCH(B17,Sessions!$A$5:$A$8,0)) -> 4-Day Program | D17: – | E17: – | F17: – | G17: – | H17: 09:50, 11:30, 14:50 | I17: 10:35, 12:15, 16:05 | J17: – | K17: – | N17: =COUNTIF('Processed Instances'!$B$5:$B$63,A17) -> 3 | O17: =SUMIF('Processed Instances'!$B$5:$B$63,A17,'Processed Instances'!$J$5:$J$63) -> 165
A18: Yara Ahmed | B18: S-103 | C18: =INDEX(Sessions!$B$5:$B$8,MATCH(B18,Sessions!$A$5:$A$8,0)) -> 4-Day Program | D18: 09:45, 13:25 | E18: 10:05, 13:35 | F18: – | G18: – | H18: – | I18: – | J18: – | K18: – | N18: =COUNTIF('Processed Instances'!$B$5:$B$63,A18) -> 2 | O18: =SUMIF('Processed Instances'!$B$5:$B$63,A18,'Processed Instances'!$J$5:$J$63) -> 30
A19: Zane Kapoor | B19: S-103 | C19: =INDEX(Sessions!$B$5:$B$8,MATCH(B19,Sessions!$A$5:$A$8,0)) -> 4-Day Program | D19: – | E19: – | F19: – | G19: – | H19: 11:10 | I19: 11:25 | J19: – | K19: – | N19: =COUNTIF('Processed Instances'!$B$5:$B$63,A19) -> 1 | O19: =SUMIF('Processed Instances'!$B$5:$B$63,A19,'Processed Instances'!$J$5:$J$63) -> 15
A20: Faisal Hassan | B20: S-104 | C20: =INDEX(Sessions!$B$5:$B$8,MATCH(B20,Sessions!$A$5:$A$8,0)) -> 5-Day Academy | D20: 09:40, 13:10 | E20: 10:00, 13:55 | F20: 13:45 | G20: 14:25 | H20: 11:40, 13:40 | I20: 12:00, 14:55 | J20: – | K20: – | L20: – | M20: – | N20: =COUNTIF('Processed Instances'!$B$5:$B$63,A20) -> 5 | O20: =SUMIF('Processed Instances'!$B$5:$B$63,A20,'Processed Instances'!$J$5:$J$63) -> 200
A21: Grace Park | B21: S-104 | C21: =INDEX(Sessions!$B$5:$B$8,MATCH(B21,Sessions!$A$5:$A$8,0)) -> 5-Day Academy | D21: 13:05 | E21: 14:20 | F21: – | G21: – | H21: – | I21: – | J21: – | K21: – | L21: – | M21: – | N21: =COUNTIF('Processed Instances'!$B$5:$B$63,A21) -> 1 | O21: =SUMIF('Processed Instances'!$B$5:$B$63,A21,'Processed Instances'!$J$5:$J$63) -> 75
A22: Harsh Malik | B22: S-104 | C22: =INDEX(Sessions!$B$5:$B$8,MATCH(B22,Sessions!$A$5:$A$8,0)) -> 5-Day Academy | D22: 09:05 | E22: 10:20 | F22: – | G22: – | H22: – | I22: – | J22: – | K22: – | L22: – | M22: – | N22: =COUNTIF('Processed Instances'!$B$5:$B$63,A22) -> 1 | O22: =SUMIF('Processed Instances'!$B$5:$B$63,A22,'Processed Instances'!$J$5:$J$63) -> 75
A23: Kiran Bhat | B23: S-104 | C23: =INDEX(Sessions!$B$5:$B$8,MATCH(B23,Sessions!$A$5:$A$8,0)) -> 5-Day Academy | D23: – | E23: – | F23: 11:35, 14:40, 16:15 | G23: 11:55, 15:25, 16:35 | H23: 09:40, 12:00 | I23: 10:40, 12:45 | J23: – | K23: – | L23: 10:00, 14:05, 15:50 | M23: 10:20, 14:20, 16:20 | N23: =COUNTIF('Processed Instances'!$B$5:$B$63,A23) -> 8 | O23: =SUMIF('Processed Instances'!$B$5:$B$63,A23,'Processed Instances'!$J$5:$J$63) -> 255
A24: Leela Hughes | B24: S-104 | C24: =INDEX(Sessions!$B$5:$B$8,MATCH(B24,Sessions!$A$5:$A$8,0)) -> 5-Day Academy | D24: – | E24: – | F24: – | G24: – | H24: 14:30 | I24: 14:45 | J24: 13:15 | K24: 13:30 | L24: 09:55, 11:20, 16:10 | M24: 10:20, 11:40, 16:40 | N24: =COUNTIF('Processed Instances'!$B$5:$B$63,A24) -> 5 | O24: =SUMIF('Processed Instances'!$B$5:$B$63,A24,'Processed Instances'!$J$5:$J$63) -> 105
A25: Marco Rossi | B25: S-104 | C25: =INDEX(Sessions!$B$5:$B$8,MATCH(B25,Sessions!$A$5:$A$8,0)) -> 5-Day Academy | D25: – | E25: – | F25: – | G25: – | H25: 14:20 | I25: 15:00 | J25: 13:15, 14:50 | K25: 14:30, 15:35 | L25: – | M25: – | N25: =COUNTIF('Processed Instances'!$B$5:$B$63,A25) -> 3 | O25: =SUMIF('Processed Instances'!$B$5:$B$63,A25,'Processed Instances'!$J$5:$J$63) -> 160
